#VRML_SIM R2019a utf8
WorldInfo {
}
Viewpoint {
  orientation -0.5027490743870666 0.833114785669465 0.23057129505181095 1.0064380484503828
  position 1.2016758927625233 1.471328008712381 1.593695068825657
}
TexturedBackground {
}
TexturedBackgroundLight {
}
Floor {
}
Solid {
  translation 0 0.25 0
  children [
    Shape {
      appearance PBRAppearance {
        baseColor 0.20392156862745098 0.396078431372549 0.6431372549019608
        roughness 1
        metalness 0
      }
      geometry Cylinder {
        height 0.5
        radius 0.05
      }
    }
    HingeJoint {
      jointParameters HingeJointParameters {
        axis 0 1 0
        anchor 0 0.255 0
        staticFriction 0.15
      }
      endPoint Solid {
        translation 0 0.255 0
        children [
          Shape {
            appearance PBRAppearance {
              baseColor 0.9372549019607843 0.1607843137254902 0.1607843137254902
              roughness 1
              metalness 0
            }
            geometry Box {
              size 0.8 0.01 0.1
            }
          }
        ]
        physics Physics {
        }
      }
    }
    HingeJoint {
      jointParameters HingeJointParameters {
        axis 0 1 0
      }
      endPoint Solid {
        translation 0 0 0.055
        rotation 0 0.9999999999999999 0 4.712388966
        children [
          Shape {
            appearance PBRAppearance {
              baseColor 0.6431372549019608 0 0
            }
            geometry Box {
              size 0.01 0.03 0.1
            }
          }
        ]
        name "solid(1)"
        physics Physics {
        }
      }
    }
  ]
}
